<?xml version="1.0" ?>
<sdf version="1.3">

  <model name="test_robot">
   <static>false</static>
      <link name="base_link">
        <pose>0 0 0.5 0 0 0</pose>
        <inertial>
          <pose>0 0 0.5 0 0 0</pose>
          <inertia>
            <ixx>1</ixx>
            <ixy>0</ixy>
            <ixz>0</ixz>
            <iyy>1</iyy>
            <iyz>0</iyz>
            <izz>1</izz>
          </inertia>
          <mass>1</mass>
        </inertial>
        <collision name="collision">
          <geometry>
            <box>
              <size>1 1 1</size>
            </box>
          </geometry>
        </collision>
        <visual name="visual">
          <geometry>
            <box>
              <size>1 1 1</size>
            </box>
          </geometry>
        </visual>
      </link>

      <link name="test_link1">
        <pose> 0 0 1.3 0 0 0 </pose>
        <inertial>
          <pose>0 0 0.5 0 0 0</pose>
          <inertia>
            <ixx>1</ixx>
            <ixy>0</ixy>
            <ixz>0</ixz>
            <iyy>1</iyy>
            <iyz>0</iyz>
            <izz>1</izz>
          </inertia>
          <mass>1</mass>
        </inertial>
        <collision name="collision">
          <geometry>
            <box>
              <size>.5 .5 .8</size>
            </box>>
          </geometry>
        </collision>
        <visual name="visual">
          <geometry>
            <box>
              <size>.5 .5 .8</size>
            </box>>
          </geometry>
        </visual>
      </link>

      <joint name="my_joint1" type="revolute">
        <parent>base_link</parent>
        <child>test_link1</child>
        <axis>
        <xyz>0 0 1</xyz>
        </axis>
      </joint>

      <link name="test_link2">
        <pose> 0 0 2.0 0 0 0 </pose>
        <inertial>
          <pose>0 0 0.5 0 0 0</pose>
          <inertia>
            <ixx>1</ixx>
            <ixy>0</ixy>
            <ixz>0</ixz>
            <iyy>1</iyy>
            <iyz>0</iyz>
            <izz>1</izz>
          </inertia>
          <mass>1</mass>
        </inertial>
        <collision name="collision">
          <geometry>
            <box>
              <size>.5 .5 .5</size>
            </box>>
          </geometry>
        </collision>
        <visual name="visual">
          <geometry>
            <box>
              <size>.5 .5 .5</size>
            </box>>
          </geometry>
        </visual>
      </link>

      <joint name="my_joint2" type="revolute">
        <parent>test_link1</parent>
        <child>test_link2</child>
        <axis>
        <xyz>0 0 1</xyz>
        </axis>
      </joint>

      <link name="test_link3">
        <pose> 0.8 0 2.0 0 0 0 </pose>
        <inertial>
          <pose>0 0 0.5 0 0 0</pose>
          <inertia>
            <ixx>1</ixx>
            <ixy>0</ixy>
            <ixz>0</ixz>
            <iyy>1</iyy>
            <iyz>0</iyz>
            <izz>1</izz>
          </inertia>
          <mass>1</mass>
        </inertial>
        <collision name="collision">
          <geometry>
            <box>
              <size>.5 .5 .5</size>
            </box>>
          </geometry>
        </collision>
        <visual name="visual">
          <geometry>
            <box>
              <size>.5 .5 .5</size>
            </box>>
          </geometry>
        </visual>
      </link>

      <joint name="my_joint3" type="revolute">
        <parent>test_link2</parent>
        <child>test_link3</child>
        <axis>
        <xyz>1 0 0</xyz>
        </axis>
      </joint>

     <plugin name="generic_controller" filename="libgeneric_controller_plugin.so">
       <controller joint_name="my_joint1">
         <type>position</type>
         <pid>10.0 0.1 0.1</pid>
       </controller>
       <controller joint_name="my_joint2">
         <type>velocity</type>
         <pid>1.0 0.1 0.01</pid>
       </controller>
       <controller joint_name="my_joint3">
         <type>velocity</type>
         <pid>1.0 0.1 0.01</pid>
       </controller>
     </plugin>
  </model>
</sdf>
