<sdf version='1.6'>
  <world name='default'>
    <light name='sun' type='directional'>
      <cast_shadows>1</cast_shadows>
      <pose frame=''>-11.8208 -19.3843 17.2198 0 -0 0</pose>
      <diffuse>0.7 0.7 0.7 1</diffuse>
      <specular>0.2 0.2 0.2 1</specular>
      <attenuation>
        <range>1000</range>
        <constant>0.9</constant>
        <linear>0.01</linear>
        <quadratic>0.001</quadratic>
      </attenuation>
      <direction>0.3698 0.4 -0.5</direction>
    </light>
    <model name='plane'>
      <static>1</static>
      <link name='link'>
        <collision name='collision'>
          <pose frame=''>0 0 0 0 -0 0</pose>
          <geometry>
            <box>
              <size>100 100 0.1</size>
            </box>
          </geometry>
          <surface>
            <friction>
              <ode>
                <mu>0.8</mu>
                <mu2>0.8</mu2>
              </ode>
              <torsional>
                <ode/>
              </torsional>
            </friction>
            <contact>
              <ode/>
            </contact>
            <bounce/>
          </surface>
          <max_contacts>10</max_contacts>
        </collision>
        <visual name='visual'>
          <cast_shadows>0</cast_shadows>
          <pose frame=''>0 0 0 0 -0 0</pose>
          <geometry>
            <box>
              <size>100 100 0.001</size>
            </box>
          </geometry>
          <material>
            <script>
              <name>Gazebo/Grey</name>
              <uri>__default__</uri>
            </script>
          </material>
        </visual>
        <self_collide>1</self_collide>
        <kinematic>0</kinematic>
        <gravity>1</gravity>
      </link>
    </model>
    <model name='pipe'>
      <static>1</static>
      <link name='link_pipe'>
        <collision name='collision_pipe'>
          <pose frame=''>3 1 0.75 0 -0 0</pose>
          <geometry>
            <cylinder>
              <radius>0.15</radius>
              <length>1.5</length>
            </cylinder>
          </geometry>
          <max_contacts>10</max_contacts>
          <surface>
            <contact>
              <ode/>
            </contact>
            <bounce/>
            <friction>
              <torsional>
                <ode/>
              </torsional>
              <ode/>
            </friction>
          </surface>
        </collision>
        <visual name='visual_pipe'>
          <pose frame=''>3 1 0.75 0 -0 0</pose>
          <geometry>
            <cylinder>
              <radius>0.15</radius>
              <length>1.5</length>
            </cylinder>
          </geometry>
          <material>
            <script>
              <name>Gazebo/White</name>
              <uri>__default__</uri>
            </script>
          </material>
        </visual>
        <self_collide>0</self_collide>
        <kinematic>0</kinematic>
        <gravity>1</gravity>
      </link>
    </model>
    <scene>
      <ambient>0.4 0.4 0.4 1</ambient>
      <background>0.7 0.7 0.7 1</background>
      <shadows>1</shadows>
    </scene>
    <gravity>0 0 -9.8</gravity>
    <magnetic_field>6e-06 2.3e-05 -4.2e-05</magnetic_field>
    <atmosphere type='adiabatic'/>
    <physics name='default_physics' default='0' type='ode'>
      <max_step_size>0.001</max_step_size>
      <real_time_factor>1</real_time_factor>
      <real_time_update_rate>1000</real_time_update_rate>
    </physics>
    <spherical_coordinates>
      <surface_model>EARTH_WGS84</surface_model>
      <latitude_deg>0</latitude_deg>
      <longitude_deg>0</longitude_deg>
      <elevation>0</elevation>
      <heading_deg>0</heading_deg>
    </spherical_coordinates>
    <model name='wl_snake'>
      <link name='module_1'>
        <pose frame=''>-0 0 0.03 0 -0 0</pose>
        <inertial>
          <pose frame=''>0 0 0 0 -0 0</pose>
          <mass>0.1</mass>
          <inertia>
            <ixx>3.38e-05</ixx>
            <ixy>0</ixy>
            <ixz>0</ixz>
            <iyy>4.69e-05</iyy>
            <iyz>0</iyz>
            <izz>4.69e-05</izz>
          </inertia>
        </inertial>
        <collision name='module_1_collision'>
          <pose frame=''>0 0 0 3.14159 -1.57079 3.14159</pose>
          <geometry>
            <cylinder>
              <radius>0.026</radius>
              <length>0.03</length>
            </cylinder>
          </geometry>
          <max_contacts>10</max_contacts>
          <surface>
            <contact>
              <ode/>
            </contact>
            <bounce/>
            <friction>
              <torsional>
                <ode/>
              </torsional>
              <ode/>
            </friction>
          </surface>
        </collision>
        <visual name='module_head_visual'>
          <pose frame=''>0.025 0 0 3.14159 -1.57079 3.14159</pose>
          <geometry>
            <cylinder>
              <radius>0.025</radius>
              <length>0.05</length>
            </cylinder>
          </geometry>
          <material>
            <script>
              <name>Gazebo/Gold</name>
              <uri>__default__</uri>
            </script>
            <specular>1 1 1 1</specular>
          </material>
        </visual>
        <visual name='module_1_visual'>
          <pose frame=''>0 0 0 3.14159 -1.57079 3.14159</pose>
          <geometry>
            <cylinder>
              <radius>0.026</radius>
              <length>0.01</length>
            </cylinder>
          </geometry>
          <material>
            <script>
              <name>Gazebo/Red</name>
              <uri>__default__</uri>
            </script>
            <specular>1 1 1 1</specular>
          </material>
        </visual>
        <visual name='module_1_visual_mesh_i'>
          <pose frame=''>-0.03 0 0 3.14159 -0 -1.5708</pose>
          <geometry>
            <mesh>
              <uri>/home/li/Downloads/wheel_less_snake/src/wl_snake_description/meshes/rotary_input.dae</uri>
              <scale>1 1 1</scale>
            </mesh>
          </geometry>
          <material>
            <script>
              <name>Gazebo/Gold</name>
              <uri>__default__</uri>
            </script>
            <specular>1 1 1 1</specular>
          </material>
        </visual>
        <sensor name='snake_camera' type='camera'>
          <pose frame=''>0.15 0 0 0 -0 0</pose>
          <update_rate>30</update_rate>
          <always_on>1</always_on>
          <visualize>1</visualize>
          <topic>/snake/eye</topic>
          <camera name='snake_eye'>
            <horizontal_fov>1.5708</horizontal_fov>
            <image>
              <width>320</width>
              <height>240</height>
              <format>R8G8B8</format>
            </image>
            <clip>
              <near>0.01</near>
              <far>100</far>
            </clip>
            <noise>
              <type>gaussian</type>
              <mean>0</mean>
              <stddev>0.007</stddev>
            </noise>
          </camera>
          <plugin name='camera_controller' filename='libgazebo_ros_camera.so'>
            <alwaysOn>true</alwaysOn>
            <updateRate>0.0</updateRate>
            <cameraName>snake/camera</cameraName>
            <imageTopicName>image_raw</imageTopicName>
            <cameraInfoTopicName>camera_info</cameraInfoTopicName>
            <frameName>camera_link</frameName>
            <hackBaseline>0.07</hackBaseline>
            <distortionK1>0.0</distortionK1>
            <distortionK2>0.0</distortionK2>
            <distortionK3>0.0</distortionK3>
            <distortionT1>0.0</distortionT1>
            <distortionT2>0.0</distortionT2>
            <robotNamespace>/</robotNamespace>
          </plugin>
        </sensor>
        <sensor name='dvs' type='camera'>
          <pose frame=''>0.15 0 0 0 -0 0</pose>
          <visualize>1</visualize>
          <camera name='__default__'>
            <horizontal_fov>1.5708</horizontal_fov>
            <image>
              <width>128</width>
              <height>128</height>
            </image>
            <clip>
              <near>0.01</near>
              <far>100</far>
            </clip>
          </camera>
          <always_on>1</always_on>
          <update_rate>60</update_rate>
          <visualize>0</visualize>
          <plugin name='dvs_controller' filename='libgazebo_dvs_plugin.so'>
            <cameraName>dvs128</cameraName>
            <robotNamespace>head</robotNamespace>
            <eventThreshold>10</eventThreshold>
            <cameraInfoTopicName>dvs_info</cameraInfoTopicName>
          </plugin>
          <pose frame=''>0 0 0 0 -0 0</pose>
        </sensor>
        <self_collide>0</self_collide>
        <kinematic>0</kinematic>
        <gravity>1</gravity>
      </link>
      <joint name='joint_1' type='revolute'>
        <parent>module_1</parent>
        <child>module_2</child>
        <pose frame=''>0.035 0 0 0 -0 0</pose>
        <axis>
          <xyz>0 0 1</xyz>
          <limit>
            <lower>-1.5708</lower>
            <upper>1.5708</upper>
            <effort>7</effort>
            <velocity>2.20893</velocity>
          </limit>
          <dynamics>
            <friction>0.2</friction>
            <spring_reference>0</spring_reference>
            <spring_stiffness>0</spring_stiffness>
          </dynamics>
          <use_parent_model_frame>0</use_parent_model_frame>
        </axis>
      </joint>
      <link name='module_2'>
        <pose frame=''>-0.064 0 0.03 0 -0 0</pose>
        <inertial>
          <pose frame=''>0 0 0 0 -0 0</pose>
          <mass>0.1</mass>
          <inertia>
            <ixx>3.38e-05</ixx>
            <ixy>0</ixy>
            <ixz>0</ixz>
            <iyy>4.69e-05</iyy>
            <iyz>0</iyz>
            <izz>4.69e-05</izz>
          </inertia>
        </inertial>
        <collision name='module_2_collision'>
          <pose frame=''>0 0 0 3.14159 -1.57079 3.14159</pose>
          <geometry>
            <cylinder>
              <radius>0.026</radius>
              <length>0.03</length>
            </cylinder>
          </geometry>
          <max_contacts>10</max_contacts>
          <surface>
            <contact>
              <ode/>
            </contact>
            <bounce/>
            <friction>
              <torsional>
                <ode/>
              </torsional>
              <ode/>
            </friction>
          </surface>
        </collision>
        <visual name='module_2_visual'>
          <pose frame=''>0 0 0 3.14159 -1.57079 3.14159</pose>
          <geometry>
            <cylinder>
              <radius>0.026</radius>
              <length>0.01</length>
            </cylinder>
          </geometry>
          <material>
            <script>
              <name>Gazebo/Black</name>
              <uri>__default__</uri>
            </script>
            <specular>1 1 1 1</specular>
          </material>
        </visual>
        <visual name='module_2_visual_mesh_i'>
          <pose frame=''>-0.03 0 0 1.57079 1.57079 3.14159</pose>
          <geometry>
            <mesh>
              <uri>/home/li/Downloads/wheel_less_snake/src/wl_snake_description/meshes/rotary_input.dae</uri>
              <scale>1 1 1</scale>
            </mesh>
          </geometry>
          <material>
            <script>
              <name>Gazebo/Gold</name>
              <uri>__default__</uri>
            </script>
            <specular>1 1 1 1</specular>
          </material>
        </visual>
        <visual name='module_2_visual_mesh_o'>
          <pose frame=''>0.032 0 0 3.14159 -0 -1.5708</pose>
          <geometry>
            <mesh>
              <uri>/home/li/Downloads/wheel_less_snake/src/wl_snake_description/meshes/rotary_output.dae</uri>
              <scale>1 1 1</scale>
            </mesh>
          </geometry>
          <material>
            <script>
              <name>Gazebo/Gold</name>
              <uri>__default__</uri>
            </script>
            <specular>1 1 1 1</specular>
          </material>
        </visual>
        <self_collide>0</self_collide>
        <kinematic>0</kinematic>
        <gravity>1</gravity>
      </link>
      <joint name='joint_2' type='revolute'>
        <parent>module_2</parent>
        <child>module_3</child>
        <pose frame=''>0.035 0 0 1.5708 -0 0</pose>
        <axis>
          <xyz>0 0 1</xyz>
          <limit>
            <lower>-1.5708</lower>
            <upper>1.5708</upper>
            <effort>7</effort>
            <velocity>2.20893</velocity>
          </limit>
          <dynamics>
            <friction>0.2</friction>
            <spring_reference>0</spring_reference>
            <spring_stiffness>0</spring_stiffness>
          </dynamics>
          <use_parent_model_frame>0</use_parent_model_frame>
        </axis>
      </joint>
      <link name='module_3'>
        <pose frame=''>-0.128 0 0.03 0 -0 0</pose>
        <inertial>
          <pose frame=''>0 0 0 0 -0 0</pose>
          <mass>0.1</mass>
          <inertia>
            <ixx>3.38e-05</ixx>
            <ixy>0</ixy>
            <ixz>0</ixz>
            <iyy>4.69e-05</iyy>
            <iyz>0</iyz>
            <izz>4.69e-05</izz>
          </inertia>
        </inertial>
        <collision name='module_3_collision'>
          <pose frame=''>0 0 0 3.14159 -1.57079 3.14159</pose>
          <geometry>
            <cylinder>
              <radius>0.026</radius>
              <length>0.03</length>
            </cylinder>
          </geometry>
          <max_contacts>10</max_contacts>
          <surface>
            <contact>
              <ode/>
            </contact>
            <bounce/>
            <friction>
              <torsional>
                <ode/>
              </torsional>
              <ode/>
            </friction>
          </surface>
        </collision>
        <visual name='module_3_visual'>
          <pose frame=''>0 0 0 3.14159 -1.57079 3.14159</pose>
          <geometry>
            <cylinder>
              <radius>0.026</radius>
              <length>0.01</length>
            </cylinder>
          </geometry>
          <material>
            <script>
              <name>Gazebo/Red</name>
              <uri>__default__</uri>
            </script>
            <specular>1 1 1 1</specular>
          </material>
        </visual>
        <visual name='module_3_visual_mesh_i'>
          <pose frame=''>-0.03 0 0 0 -0 1.5708</pose>
          <geometry>
            <mesh>
              <uri>/home/li/Downloads/wheel_less_snake/src/wl_snake_description/meshes/rotary_input.dae</uri>
              <scale>1 1 1</scale>
            </mesh>
          </geometry>
          <material>
            <script>
              <name>Gazebo/Gold</name>
              <uri>__default__</uri>
            </script>
            <specular>1 1 1 1</specular>
          </material>
        </visual>
        <visual name='module_3_visual_mesh_o'>
          <pose frame=''>0.032 0 0 1.57079 1.57079 3.14159</pose>
          <geometry>
            <mesh>
              <uri>/home/li/Downloads/wheel_less_snake/src/wl_snake_description/meshes/rotary_output.dae</uri>
              <scale>1 1 1</scale>
            </mesh>
          </geometry>
          <material>
            <script>
              <name>Gazebo/Gold</name>
              <uri>__default__</uri>
            </script>
            <specular>1 1 1 1</specular>
          </material>
        </visual>
        <self_collide>0</self_collide>
        <kinematic>0</kinematic>
        <gravity>1</gravity>
      </link>
      <joint name='joint_3' type='revolute'>
        <parent>module_3</parent>
        <child>module_4</child>
        <pose frame=''>0.035 0 0 3.14159 -0 0</pose>
        <axis>
          <xyz>0 0 1</xyz>
          <limit>
            <lower>-1.5708</lower>
            <upper>1.5708</upper>
            <effort>7</effort>
            <velocity>2.20893</velocity>
          </limit>
          <dynamics>
            <friction>0.2</friction>
            <spring_reference>0</spring_reference>
            <spring_stiffness>0</spring_stiffness>
          </dynamics>
          <use_parent_model_frame>0</use_parent_model_frame>
        </axis>
      </joint>
      <link name='module_4'>
        <pose frame=''>-0.192 0 0.03 0 -0 0</pose>
        <inertial>
          <pose frame=''>0 0 0 0 -0 0</pose>
          <mass>0.1</mass>
          <inertia>
            <ixx>3.38e-05</ixx>
            <ixy>0</ixy>
            <ixz>0</ixz>
            <iyy>4.69e-05</iyy>
            <iyz>0</iyz>
            <izz>4.69e-05</izz>
          </inertia>
        </inertial>
        <collision name='module_4_collision'>
          <pose frame=''>0 0 0 3.14159 -1.57079 3.14159</pose>
          <geometry>
            <cylinder>
              <radius>0.026</radius>
              <length>0.03</length>
            </cylinder>
          </geometry>
          <max_contacts>10</max_contacts>
          <surface>
            <contact>
              <ode/>
            </contact>
            <bounce/>
            <friction>
              <torsional>
                <ode/>
              </torsional>
              <ode/>
            </friction>
          </surface>
        </collision>
        <visual name='module_4_visual'>
          <pose frame=''>0 0 0 3.14159 -1.57079 3.14159</pose>
          <geometry>
            <cylinder>
              <radius>0.026</radius>
              <length>0.01</length>
            </cylinder>
          </geometry>
          <material>
            <script>
              <name>Gazebo/Black</name>
              <uri>__default__</uri>
            </script>
            <specular>1 1 1 1</specular>
          </material>
        </visual>
        <visual name='module_4_visual_mesh_i'>
          <pose frame=''>-0.03 0 0 -1.57079 -1.57079 3.14159</pose>
          <geometry>
            <mesh>
              <uri>/home/li/Downloads/wheel_less_snake/src/wl_snake_description/meshes/rotary_input.dae</uri>
              <scale>1 1 1</scale>
            </mesh>
          </geometry>
          <material>
            <script>
              <name>Gazebo/Gold</name>
              <uri>__default__</uri>
            </script>
            <specular>1 1 1 1</specular>
          </material>
        </visual>
        <visual name='module_4_visual_mesh_o'>
          <pose frame=''>0.032 0 0 0 -0 1.5708</pose>
          <geometry>
            <mesh>
              <uri>/home/li/Downloads/wheel_less_snake/src/wl_snake_description/meshes/rotary_output.dae</uri>
              <scale>1 1 1</scale>
            </mesh>
          </geometry>
          <material>
            <script>
              <name>Gazebo/Gold</name>
              <uri>__default__</uri>
            </script>
            <specular>1 1 1 1</specular>
          </material>
        </visual>
        <self_collide>0</self_collide>
        <kinematic>0</kinematic>
        <gravity>1</gravity>
      </link>
      <joint name='joint_4' type='revolute'>
        <parent>module_4</parent>
        <child>module_5</child>
        <pose frame=''>0.035 0 0 -1.5708 -0 0</pose>
        <axis>
          <xyz>0 0 1</xyz>
          <limit>
            <lower>-1.5708</lower>
            <upper>1.5708</upper>
            <effort>7</effort>
            <velocity>2.20893</velocity>
          </limit>
          <dynamics>
            <friction>0.2</friction>
            <spring_reference>0</spring_reference>
            <spring_stiffness>0</spring_stiffness>
          </dynamics>
          <use_parent_model_frame>0</use_parent_model_frame>
        </axis>
      </joint>
      <link name='module_5'>
        <pose frame=''>-0.256 0 0.03 0 -0 0</pose>
        <inertial>
          <pose frame=''>0 0 0 0 -0 0</pose>
          <mass>0.1</mass>
          <inertia>
            <ixx>3.38e-05</ixx>
            <ixy>0</ixy>
            <ixz>0</ixz>
            <iyy>4.69e-05</iyy>
            <iyz>0</iyz>
            <izz>4.69e-05</izz>
          </inertia>
        </inertial>
        <collision name='module_5_collision'>
          <pose frame=''>0 0 0 3.14159 -1.57079 3.14159</pose>
          <geometry>
            <cylinder>
              <radius>0.026</radius>
              <length>0.03</length>
            </cylinder>
          </geometry>
          <max_contacts>10</max_contacts>
          <surface>
            <contact>
              <ode/>
            </contact>
            <bounce/>
            <friction>
              <torsional>
                <ode/>
              </torsional>
              <ode/>
            </friction>
          </surface>
        </collision>
        <visual name='module_5_visual'>
          <pose frame=''>0 0 0 3.14159 -1.57079 3.14159</pose>
          <geometry>
            <cylinder>
              <radius>0.026</radius>
              <length>0.01</length>
            </cylinder>
          </geometry>
          <material>
            <script>
              <name>Gazebo/Red</name>
              <uri>__default__</uri>
            </script>
            <specular>1 1 1 1</specular>
          </material>
        </visual>
        <visual name='module_5_visual_mesh_i'>
          <pose frame=''>-0.03 0 0 3.14159 -0 -1.5708</pose>
          <geometry>
            <mesh>
              <uri>/home/li/Downloads/wheel_less_snake/src/wl_snake_description/meshes/rotary_input.dae</uri>
              <scale>1 1 1</scale>
            </mesh>
          </geometry>
          <material>
            <script>
              <name>Gazebo/Gold</name>
              <uri>__default__</uri>
            </script>
            <specular>1 1 1 1</specular>
          </material>
        </visual>
        <visual name='module_5_visual_mesh_o'>
          <pose frame=''>0.032 0 0 -1.57079 -1.57079 3.14159</pose>
          <geometry>
            <mesh>
              <uri>/home/li/Downloads/wheel_less_snake/src/wl_snake_description/meshes/rotary_output.dae</uri>
              <scale>1 1 1</scale>
            </mesh>
          </geometry>
          <material>
            <script>
              <name>Gazebo/Gold</name>
              <uri>__default__</uri>
            </script>
            <specular>1 1 1 1</specular>
          </material>
        </visual>
        <self_collide>0</self_collide>
        <kinematic>0</kinematic>
        <gravity>1</gravity>
      </link>
      <joint name='joint_5' type='revolute'>
        <parent>module_5</parent>
        <child>module_6</child>
        <pose frame=''>0.035 0 0 0 -0 0</pose>
        <axis>
          <xyz>0 0 1</xyz>
          <limit>
            <lower>-1.5708</lower>
            <upper>1.5708</upper>
            <effort>7</effort>
            <velocity>2.20893</velocity>
          </limit>
          <dynamics>
            <friction>0.2</friction>
            <spring_reference>0</spring_reference>
            <spring_stiffness>0</spring_stiffness>
          </dynamics>
          <use_parent_model_frame>0</use_parent_model_frame>
        </axis>
      </joint>
      <link name='module_6'>
        <pose frame=''>-0.32 0 0.03 0 -0 0</pose>
        <inertial>
          <pose frame=''>0 0 0 0 -0 0</pose>
          <mass>0.1</mass>
          <inertia>
            <ixx>3.38e-05</ixx>
            <ixy>0</ixy>
            <ixz>0</ixz>
            <iyy>4.69e-05</iyy>
            <iyz>0</iyz>
            <izz>4.69e-05</izz>
          </inertia>
        </inertial>
        <collision name='module_6_collision'>
          <pose frame=''>0 0 0 3.14159 -1.57079 3.14159</pose>
          <geometry>
            <cylinder>
              <radius>0.026</radius>
              <length>0.03</length>
            </cylinder>
          </geometry>
          <max_contacts>10</max_contacts>
          <surface>
            <contact>
              <ode/>
            </contact>
            <bounce/>
            <friction>
              <torsional>
                <ode/>
              </torsional>
              <ode/>
            </friction>
          </surface>
        </collision>
        <visual name='module_6_visual'>
          <pose frame=''>0 0 0 3.14159 -1.57079 3.14159</pose>
          <geometry>
            <cylinder>
              <radius>0.026</radius>
              <length>0.01</length>
            </cylinder>
          </geometry>
          <material>
            <script>
              <name>Gazebo/Black</name>
              <uri>__default__</uri>
            </script>
            <specular>1 1 1 1</specular>
          </material>
        </visual>
        <visual name='module_6_visual_mesh_i'>
          <pose frame=''>-0.03 0 0 1.57079 1.57079 3.14159</pose>
          <geometry>
            <mesh>
              <uri>/home/li/Downloads/wheel_less_snake/src/wl_snake_description/meshes/rotary_input.dae</uri>
              <scale>1 1 1</scale>
            </mesh>
          </geometry>
          <material>
            <script>
              <name>Gazebo/Gold</name>
              <uri>__default__</uri>
            </script>
            <specular>1 1 1 1</specular>
          </material>
        </visual>
        <visual name='module_6_visual_mesh_o'>
          <pose frame=''>0.032 0 0 3.14159 -0 -1.5708</pose>
          <geometry>
            <mesh>
              <uri>/home/li/Downloads/wheel_less_snake/src/wl_snake_description/meshes/rotary_output.dae</uri>
              <scale>1 1 1</scale>
            </mesh>
          </geometry>
          <material>
            <script>
              <name>Gazebo/Gold</name>
              <uri>__default__</uri>
            </script>
            <specular>1 1 1 1</specular>
          </material>
        </visual>
        <self_collide>0</self_collide>
        <kinematic>0</kinematic>
        <gravity>1</gravity>
      </link>
      <joint name='joint_6' type='revolute'>
        <parent>module_6</parent>
        <child>module_7</child>
        <pose frame=''>0.035 0 0 1.5708 -0 0</pose>
        <axis>
          <xyz>0 0 1</xyz>
          <limit>
            <lower>-1.5708</lower>
            <upper>1.5708</upper>
            <effort>7</effort>
            <velocity>2.20893</velocity>
          </limit>
          <dynamics>
            <friction>0.2</friction>
            <spring_reference>0</spring_reference>
            <spring_stiffness>0</spring_stiffness>
          </dynamics>
          <use_parent_model_frame>0</use_parent_model_frame>
        </axis>
      </joint>
      <link name='module_7'>
        <pose frame=''>-0.384 0 0.03 0 -0 0</pose>
        <inertial>
          <pose frame=''>0 0 0 0 -0 0</pose>
          <mass>0.1</mass>
          <inertia>
            <ixx>3.38e-05</ixx>
            <ixy>0</ixy>
            <ixz>0</ixz>
            <iyy>4.69e-05</iyy>
            <iyz>0</iyz>
            <izz>4.69e-05</izz>
          </inertia>
        </inertial>
        <collision name='module_7_collision'>
          <pose frame=''>0 0 0 3.14159 -1.57079 3.14159</pose>
          <geometry>
            <cylinder>
              <radius>0.026</radius>
              <length>0.03</length>
            </cylinder>
          </geometry>
          <max_contacts>10</max_contacts>
          <surface>
            <contact>
              <ode/>
            </contact>
            <bounce/>
            <friction>
              <torsional>
                <ode/>
              </torsional>
              <ode/>
            </friction>
          </surface>
        </collision>
        <visual name='module_7_visual'>
          <pose frame=''>0 0 0 3.14159 -1.57079 3.14159</pose>
          <geometry>
            <cylinder>
              <radius>0.026</radius>
              <length>0.01</length>
            </cylinder>
          </geometry>
          <material>
            <script>
              <name>Gazebo/Red</name>
              <uri>__default__</uri>
            </script>
            <specular>1 1 1 1</specular>
          </material>
        </visual>
        <visual name='module_7_visual_mesh_i'>
          <pose frame=''>-0.03 0 0 0 -0 1.5708</pose>
          <geometry>
            <mesh>
              <uri>/home/li/Downloads/wheel_less_snake/src/wl_snake_description/meshes/rotary_input.dae</uri>
              <scale>1 1 1</scale>
            </mesh>
          </geometry>
          <material>
            <script>
              <name>Gazebo/Gold</name>
              <uri>__default__</uri>
            </script>
            <specular>1 1 1 1</specular>
          </material>
        </visual>
        <visual name='module_7_visual_mesh_o'>
          <pose frame=''>0.032 0 0 1.57079 1.57079 3.14159</pose>
          <geometry>
            <mesh>
              <uri>/home/li/Downloads/wheel_less_snake/src/wl_snake_description/meshes/rotary_output.dae</uri>
              <scale>1 1 1</scale>
            </mesh>
          </geometry>
          <material>
            <script>
              <name>Gazebo/Gold</name>
              <uri>__default__</uri>
            </script>
            <specular>1 1 1 1</specular>
          </material>
        </visual>
        <self_collide>0</self_collide>
        <kinematic>0</kinematic>
        <gravity>1</gravity>
      </link>
      <joint name='joint_7' type='revolute'>
        <parent>module_7</parent>
        <child>module_8</child>
        <pose frame=''>0.035 0 0 3.14159 -0 0</pose>
        <axis>
          <xyz>0 0 1</xyz>
          <limit>
            <lower>-1.5708</lower>
            <upper>1.5708</upper>
            <effort>7</effort>
            <velocity>2.20893</velocity>
          </limit>
          <dynamics>
            <friction>0.2</friction>
            <spring_reference>0</spring_reference>
            <spring_stiffness>0</spring_stiffness>
          </dynamics>
          <use_parent_model_frame>0</use_parent_model_frame>
        </axis>
      </joint>
      <link name='module_8'>
        <pose frame=''>-0.448 0 0.03 0 -0 0</pose>
        <inertial>
          <pose frame=''>0 0 0 0 -0 0</pose>
          <mass>0.1</mass>
          <inertia>
            <ixx>3.38e-05</ixx>
            <ixy>0</ixy>
            <ixz>0</ixz>
            <iyy>4.69e-05</iyy>
            <iyz>0</iyz>
            <izz>4.69e-05</izz>
          </inertia>
        </inertial>
        <collision name='module_8_collision'>
          <pose frame=''>0 0 0 3.14159 -1.57079 3.14159</pose>
          <geometry>
            <cylinder>
              <radius>0.026</radius>
              <length>0.03</length>
            </cylinder>
          </geometry>
          <max_contacts>10</max_contacts>
          <surface>
            <contact>
              <ode/>
            </contact>
            <bounce/>
            <friction>
              <torsional>
                <ode/>
              </torsional>
              <ode/>
            </friction>
          </surface>
        </collision>
        <visual name='module_8_visual'>
          <pose frame=''>0 0 0 3.14159 -1.57079 3.14159</pose>
          <geometry>
            <cylinder>
              <radius>0.026</radius>
              <length>0.01</length>
            </cylinder>
          </geometry>
          <material>
            <script>
              <name>Gazebo/Black</name>
              <uri>__default__</uri>
            </script>
            <specular>1 1 1 1</specular>
          </material>
        </visual>
        <visual name='module_8_visual_mesh_i'>
          <pose frame=''>-0.03 0 0 -1.57079 -1.57079 3.14159</pose>
          <geometry>
            <mesh>
              <uri>/home/li/Downloads/wheel_less_snake/src/wl_snake_description/meshes/rotary_input.dae</uri>
              <scale>1 1 1</scale>
            </mesh>
          </geometry>
          <material>
            <script>
              <name>Gazebo/Gold</name>
              <uri>__default__</uri>
            </script>
            <specular>1 1 1 1</specular>
          </material>
        </visual>
        <visual name='module_8_visual_mesh_o'>
          <pose frame=''>0.032 0 0 0 -0 1.5708</pose>
          <geometry>
            <mesh>
              <uri>/home/li/Downloads/wheel_less_snake/src/wl_snake_description/meshes/rotary_output.dae</uri>
              <scale>1 1 1</scale>
            </mesh>
          </geometry>
          <material>
            <script>
              <name>Gazebo/Gold</name>
              <uri>__default__</uri>
            </script>
            <specular>1 1 1 1</specular>
          </material>
        </visual>
        <self_collide>0</self_collide>
        <kinematic>0</kinematic>
        <gravity>1</gravity>
      </link>
      <joint name='joint_8' type='revolute'>
        <parent>module_8</parent>
        <child>module_9</child>
        <pose frame=''>0.035 0 0 -1.5708 -0 0</pose>
        <axis>
          <xyz>0 0 1</xyz>
          <limit>
            <lower>-1.5708</lower>
            <upper>1.5708</upper>
            <effort>7</effort>
            <velocity>2.20893</velocity>
          </limit>
          <dynamics>
            <friction>0.2</friction>
            <spring_reference>0</spring_reference>
            <spring_stiffness>0</spring_stiffness>
          </dynamics>
          <use_parent_model_frame>0</use_parent_model_frame>
        </axis>
      </joint>
      <link name='module_9'>
        <pose frame=''>-0.512 0 0.03 0 -0 0</pose>
        <inertial>
          <pose frame=''>0 0 0 0 -0 0</pose>
          <mass>0.1</mass>
          <inertia>
            <ixx>3.38e-05</ixx>
            <ixy>0</ixy>
            <ixz>0</ixz>
            <iyy>4.69e-05</iyy>
            <iyz>0</iyz>
            <izz>4.69e-05</izz>
          </inertia>
        </inertial>
        <collision name='module_9_collision'>
          <pose frame=''>0 0 0 3.14159 -1.57079 3.14159</pose>
          <geometry>
            <cylinder>
              <radius>0.026</radius>
              <length>0.03</length>
            </cylinder>
          </geometry>
          <max_contacts>10</max_contacts>
          <surface>
            <contact>
              <ode/>
            </contact>
            <bounce/>
            <friction>
              <torsional>
                <ode/>
              </torsional>
              <ode/>
            </friction>
          </surface>
        </collision>
        <visual name='module_9_visual'>
          <pose frame=''>0 0 0 3.14159 -1.57079 3.14159</pose>
          <geometry>
            <cylinder>
              <radius>0.026</radius>
              <length>0.01</length>
            </cylinder>
          </geometry>
          <material>
            <script>
              <name>Gazebo/Red</name>
              <uri>__default__</uri>
            </script>
            <specular>1 1 1 1</specular>
          </material>
        </visual>
        <visual name='module_9_visual_mesh_i'>
          <pose frame=''>-0.03 0 0 3.14159 -0 -1.5708</pose>
          <geometry>
            <mesh>
              <uri>/home/li/Downloads/wheel_less_snake/src/wl_snake_description/meshes/rotary_input.dae</uri>
              <scale>1 1 1</scale>
            </mesh>
          </geometry>
          <material>
            <script>
              <name>Gazebo/Gold</name>
              <uri>__default__</uri>
            </script>
            <specular>1 1 1 1</specular>
          </material>
        </visual>
        <visual name='module_9_visual_mesh_o'>
          <pose frame=''>0.032 0 0 -1.57079 -1.57079 3.14159</pose>
          <geometry>
            <mesh>
              <uri>/home/li/Downloads/wheel_less_snake/src/wl_snake_description/meshes/rotary_output.dae</uri>
              <scale>1 1 1</scale>
            </mesh>
          </geometry>
          <material>
            <script>
              <name>Gazebo/Gold</name>
              <uri>__default__</uri>
            </script>
            <specular>1 1 1 1</specular>
          </material>
        </visual>
        <self_collide>0</self_collide>
        <kinematic>0</kinematic>
        <gravity>1</gravity>
      </link>
      <joint name='joint_9' type='revolute'>
        <parent>module_9</parent>
        <child>module_10</child>
        <pose frame=''>0.035 0 0 0 -0 0</pose>
        <axis>
          <xyz>0 0 1</xyz>
          <limit>
            <lower>-1.5708</lower>
            <upper>1.5708</upper>
            <effort>7</effort>
            <velocity>2.20893</velocity>
          </limit>
          <dynamics>
            <friction>0.2</friction>
            <spring_reference>0</spring_reference>
            <spring_stiffness>0</spring_stiffness>
          </dynamics>
          <use_parent_model_frame>0</use_parent_model_frame>
        </axis>
      </joint>
      <link name='module_10'>
        <pose frame=''>-0.576 0 0.03 0 -0 0</pose>
        <inertial>
          <pose frame=''>0 0 0 0 -0 0</pose>
          <mass>0.1</mass>
          <inertia>
            <ixx>3.38e-05</ixx>
            <ixy>0</ixy>
            <ixz>0</ixz>
            <iyy>4.69e-05</iyy>
            <iyz>0</iyz>
            <izz>4.69e-05</izz>
          </inertia>
        </inertial>
        <collision name='module_10_collision'>
          <pose frame=''>0 0 0 3.14159 -1.57079 3.14159</pose>
          <geometry>
            <cylinder>
              <radius>0.026</radius>
              <length>0.03</length>
            </cylinder>
          </geometry>
          <max_contacts>10</max_contacts>
          <surface>
            <contact>
              <ode/>
            </contact>
            <bounce/>
            <friction>
              <torsional>
                <ode/>
              </torsional>
              <ode/>
            </friction>
          </surface>
        </collision>
        <visual name='module_10_visual'>
          <pose frame=''>0 0 0 3.14159 -1.57079 3.14159</pose>
          <geometry>
            <cylinder>
              <radius>0.026</radius>
              <length>0.01</length>
            </cylinder>
          </geometry>
          <material>
            <script>
              <name>Gazebo/Black</name>
              <uri>__default__</uri>
            </script>
            <specular>1 1 1 1</specular>
          </material>
        </visual>
        <visual name='module_10_visual_mesh_i'>
          <pose frame=''>-0.03 0 0 1.57079 1.57079 3.14159</pose>
          <geometry>
            <mesh>
              <uri>/home/li/Downloads/wheel_less_snake/src/wl_snake_description/meshes/rotary_input.dae</uri>
              <scale>1 1 1</scale>
            </mesh>
          </geometry>
          <material>
            <script>
              <name>Gazebo/Gold</name>
              <uri>__default__</uri>
            </script>
            <specular>1 1 1 1</specular>
          </material>
        </visual>
        <visual name='module_10_visual_mesh_o'>
          <pose frame=''>0.032 0 0 3.14159 -0 -1.5708</pose>
          <geometry>
            <mesh>
              <uri>/home/li/Downloads/wheel_less_snake/src/wl_snake_description/meshes/rotary_output.dae</uri>
              <scale>1 1 1</scale>
            </mesh>
          </geometry>
          <material>
            <script>
              <name>Gazebo/Gold</name>
              <uri>__default__</uri>
            </script>
            <specular>1 1 1 1</specular>
          </material>
        </visual>
        <self_collide>0</self_collide>
        <kinematic>0</kinematic>
        <gravity>1</gravity>
      </link>
      <joint name='joint_10' type='revolute'>
        <parent>module_10</parent>
        <child>module_11</child>
        <pose frame=''>0.035 0 0 1.5708 -0 0</pose>
        <axis>
          <xyz>0 0 1</xyz>
          <limit>
            <lower>-1.5708</lower>
            <upper>1.5708</upper>
            <effort>7</effort>
            <velocity>2.20893</velocity>
          </limit>
          <dynamics>
            <friction>0.2</friction>
            <spring_reference>0</spring_reference>
            <spring_stiffness>0</spring_stiffness>
          </dynamics>
          <use_parent_model_frame>0</use_parent_model_frame>
        </axis>
      </joint>
      <link name='module_11'>
        <pose frame=''>-0.64 0 0.03 0 -0 0</pose>
        <inertial>
          <pose frame=''>0 0 0 0 -0 0</pose>
          <mass>0.1</mass>
          <inertia>
            <ixx>3.38e-05</ixx>
            <ixy>0</ixy>
            <ixz>0</ixz>
            <iyy>4.69e-05</iyy>
            <iyz>0</iyz>
            <izz>4.69e-05</izz>
          </inertia>
        </inertial>
        <collision name='module_11_collision'>
          <pose frame=''>0 0 0 3.14159 -1.57079 3.14159</pose>
          <geometry>
            <cylinder>
              <radius>0.026</radius>
              <length>0.03</length>
            </cylinder>
          </geometry>
          <max_contacts>10</max_contacts>
          <surface>
            <contact>
              <ode/>
            </contact>
            <bounce/>
            <friction>
              <torsional>
                <ode/>
              </torsional>
              <ode/>
            </friction>
          </surface>
        </collision>
        <visual name='module_11_visual'>
          <pose frame=''>0 0 0 3.14159 -1.57079 3.14159</pose>
          <geometry>
            <cylinder>
              <radius>0.026</radius>
              <length>0.01</length>
            </cylinder>
          </geometry>
          <material>
            <script>
              <name>Gazebo/Red</name>
              <uri>__default__</uri>
            </script>
            <specular>1 1 1 1</specular>
          </material>
        </visual>
        <visual name='module_11_visual_mesh_i'>
          <pose frame=''>-0.03 0 0 0 -0 1.5708</pose>
          <geometry>
            <mesh>
              <uri>/home/li/Downloads/wheel_less_snake/src/wl_snake_description/meshes/rotary_input.dae</uri>
              <scale>1 1 1</scale>
            </mesh>
          </geometry>
          <material>
            <script>
              <name>Gazebo/Gold</name>
              <uri>__default__</uri>
            </script>
            <specular>1 1 1 1</specular>
          </material>
        </visual>
        <visual name='module_11_visual_mesh_o'>
          <pose frame=''>0.032 0 0 1.57079 1.57079 3.14159</pose>
          <geometry>
            <mesh>
              <uri>/home/li/Downloads/wheel_less_snake/src/wl_snake_description/meshes/rotary_output.dae</uri>
              <scale>1 1 1</scale>
            </mesh>
          </geometry>
          <material>
            <script>
              <name>Gazebo/Gold</name>
              <uri>__default__</uri>
            </script>
            <specular>1 1 1 1</specular>
          </material>
        </visual>
        <self_collide>0</self_collide>
        <kinematic>0</kinematic>
        <gravity>1</gravity>
      </link>
      <joint name='joint_11' type='revolute'>
        <parent>module_11</parent>
        <child>module_12</child>
        <pose frame=''>0.035 0 0 3.14159 -0 0</pose>
        <axis>
          <xyz>0 0 1</xyz>
          <limit>
            <lower>-1.5708</lower>
            <upper>1.5708</upper>
            <effort>7</effort>
            <velocity>2.20893</velocity>
          </limit>
          <dynamics>
            <friction>0.2</friction>
            <spring_reference>0</spring_reference>
            <spring_stiffness>0</spring_stiffness>
          </dynamics>
          <use_parent_model_frame>0</use_parent_model_frame>
        </axis>
      </joint>
      <link name='module_12'>
        <pose frame=''>-0.704 0 0.03 0 -0 0</pose>
        <inertial>
          <pose frame=''>0 0 0 0 -0 0</pose>
          <mass>0.1</mass>
          <inertia>
            <ixx>3.38e-05</ixx>
            <ixy>0</ixy>
            <ixz>0</ixz>
            <iyy>4.69e-05</iyy>
            <iyz>0</iyz>
            <izz>4.69e-05</izz>
          </inertia>
        </inertial>
        <collision name='module_12_collision'>
          <pose frame=''>0 0 0 3.14159 -1.57079 3.14159</pose>
          <geometry>
            <cylinder>
              <radius>0.026</radius>
              <length>0.03</length>
            </cylinder>
          </geometry>
          <max_contacts>10</max_contacts>
          <surface>
            <contact>
              <ode/>
            </contact>
            <bounce/>
            <friction>
              <torsional>
                <ode/>
              </torsional>
              <ode/>
            </friction>
          </surface>
        </collision>
        <visual name='module_12_visual'>
          <pose frame=''>0 0 0 3.14159 -1.57079 3.14159</pose>
          <geometry>
            <cylinder>
              <radius>0.026</radius>
              <length>0.01</length>
            </cylinder>
          </geometry>
          <material>
            <script>
              <name>Gazebo/Black</name>
              <uri>__default__</uri>
            </script>
            <specular>1 1 1 1</specular>
          </material>
        </visual>
        <visual name='module_12_visual_mesh_i'>
          <pose frame=''>-0.03 0 0 -1.57079 -1.57079 3.14159</pose>
          <geometry>
            <mesh>
              <uri>/home/li/Downloads/wheel_less_snake/src/wl_snake_description/meshes/rotary_input.dae</uri>
              <scale>1 1 1</scale>
            </mesh>
          </geometry>
          <material>
            <script>
              <name>Gazebo/Gold</name>
              <uri>__default__</uri>
            </script>
            <specular>1 1 1 1</specular>
          </material>
        </visual>
        <visual name='module_12_visual_mesh_o'>
          <pose frame=''>0.032 0 0 0 -0 1.5708</pose>
          <geometry>
            <mesh>
              <uri>/home/li/Downloads/wheel_less_snake/src/wl_snake_description/meshes/rotary_output.dae</uri>
              <scale>1 1 1</scale>
            </mesh>
          </geometry>
          <material>
            <script>
              <name>Gazebo/Gold</name>
              <uri>__default__</uri>
            </script>
            <specular>1 1 1 1</specular>
          </material>
        </visual>
        <self_collide>0</self_collide>
        <kinematic>0</kinematic>
        <gravity>1</gravity>
      </link>
      <joint name='joint_12' type='revolute'>
        <parent>module_12</parent>
        <child>module_13</child>
        <pose frame=''>0.035 0 0 -1.5708 -0 0</pose>
        <axis>
          <xyz>0 0 1</xyz>
          <limit>
            <lower>-1.5708</lower>
            <upper>1.5708</upper>
            <effort>7</effort>
            <velocity>2.20893</velocity>
          </limit>
          <dynamics>
            <friction>0.2</friction>
            <spring_reference>0</spring_reference>
            <spring_stiffness>0</spring_stiffness>
          </dynamics>
          <use_parent_model_frame>0</use_parent_model_frame>
        </axis>
      </joint>
      <link name='module_13'>
        <pose frame=''>-0.768 0 0.03 0 -0 0</pose>
        <inertial>
          <pose frame=''>0 0 0 0 -0 0</pose>
          <mass>0.1</mass>
          <inertia>
            <ixx>3.38e-05</ixx>
            <ixy>0</ixy>
            <ixz>0</ixz>
            <iyy>4.69e-05</iyy>
            <iyz>0</iyz>
            <izz>4.69e-05</izz>
          </inertia>
        </inertial>
        <collision name='module_13_collision'>
          <pose frame=''>0 0 0 3.14159 -1.57079 3.14159</pose>
          <geometry>
            <cylinder>
              <radius>0.026</radius>
              <length>0.03</length>
            </cylinder>
          </geometry>
          <max_contacts>10</max_contacts>
          <surface>
            <contact>
              <ode/>
            </contact>
            <bounce/>
            <friction>
              <torsional>
                <ode/>
              </torsional>
              <ode/>
            </friction>
          </surface>
        </collision>
        <visual name='module_13_visual'>
          <pose frame=''>0 0 0 3.14159 -1.57079 3.14159</pose>
          <geometry>
            <cylinder>
              <radius>0.026</radius>
              <length>0.01</length>
            </cylinder>
          </geometry>
          <material>
            <script>
              <name>Gazebo/Red</name>
              <uri>__default__</uri>
            </script>
            <specular>1 1 1 1</specular>
          </material>
        </visual>
        <visual name='module_13_visual_mesh_i'>
          <pose frame=''>-0.03 0 0 3.14159 -0 -1.5708</pose>
          <geometry>
            <mesh>
              <uri>/home/li/Downloads/wheel_less_snake/src/wl_snake_description/meshes/rotary_input.dae</uri>
              <scale>1 1 1</scale>
            </mesh>
          </geometry>
          <material>
            <script>
              <name>Gazebo/Gold</name>
              <uri>__default__</uri>
            </script>
            <specular>1 1 1 1</specular>
          </material>
        </visual>
        <visual name='module_13_visual_mesh_o'>
          <pose frame=''>0.032 0 0 -1.57079 -1.57079 3.14159</pose>
          <geometry>
            <mesh>
              <uri>/home/li/Downloads/wheel_less_snake/src/wl_snake_description/meshes/rotary_output.dae</uri>
              <scale>1 1 1</scale>
            </mesh>
          </geometry>
          <material>
            <script>
              <name>Gazebo/Gold</name>
              <uri>__default__</uri>
            </script>
            <specular>1 1 1 1</specular>
          </material>
        </visual>
        <self_collide>0</self_collide>
        <kinematic>0</kinematic>
        <gravity>1</gravity>
      </link>
      <joint name='joint_13' type='revolute'>
        <parent>module_13</parent>
        <child>module_14</child>
        <pose frame=''>0.035 0 0 0 -0 0</pose>
        <axis>
          <xyz>0 0 1</xyz>
          <limit>
            <lower>-1.5708</lower>
            <upper>1.5708</upper>
            <effort>7</effort>
            <velocity>2.20893</velocity>
          </limit>
          <dynamics>
            <friction>0.2</friction>
            <spring_reference>0</spring_reference>
            <spring_stiffness>0</spring_stiffness>
          </dynamics>
          <use_parent_model_frame>0</use_parent_model_frame>
        </axis>
      </joint>
      <link name='module_14'>
        <pose frame=''>-0.832 0 0.03 0 -0 0</pose>
        <inertial>
          <pose frame=''>0 0 0 0 -0 0</pose>
          <mass>0.1</mass>
          <inertia>
            <ixx>3.38e-05</ixx>
            <ixy>0</ixy>
            <ixz>0</ixz>
            <iyy>4.69e-05</iyy>
            <iyz>0</iyz>
            <izz>4.69e-05</izz>
          </inertia>
        </inertial>
        <collision name='module_14_collision'>
          <pose frame=''>0 0 0 3.14159 -1.57079 3.14159</pose>
          <geometry>
            <cylinder>
              <radius>0.026</radius>
              <length>0.03</length>
            </cylinder>
          </geometry>
          <max_contacts>10</max_contacts>
          <surface>
            <contact>
              <ode/>
            </contact>
            <bounce/>
            <friction>
              <torsional>
                <ode/>
              </torsional>
              <ode/>
            </friction>
          </surface>
        </collision>
        <visual name='module_14_visual'>
          <pose frame=''>0 0 0 3.14159 -1.57079 3.14159</pose>
          <geometry>
            <cylinder>
              <radius>0.026</radius>
              <length>0.01</length>
            </cylinder>
          </geometry>
          <material>
            <script>
              <name>Gazebo/Black</name>
              <uri>__default__</uri>
            </script>
            <specular>1 1 1 1</specular>
          </material>
        </visual>
        <visual name='module_14_visual_mesh_i'>
          <pose frame=''>-0.03 0 0 1.57079 1.57079 3.14159</pose>
          <geometry>
            <mesh>
              <uri>/home/li/Downloads/wheel_less_snake/src/wl_snake_description/meshes/rotary_input.dae</uri>
              <scale>1 1 1</scale>
            </mesh>
          </geometry>
          <material>
            <script>
              <name>Gazebo/Gold</name>
              <uri>__default__</uri>
            </script>
            <specular>1 1 1 1</specular>
          </material>
        </visual>
        <visual name='module_14_visual_mesh_o'>
          <pose frame=''>0.032 0 0 3.14159 -0 -1.5708</pose>
          <geometry>
            <mesh>
              <uri>/home/li/Downloads/wheel_less_snake/src/wl_snake_description/meshes/rotary_output.dae</uri>
              <scale>1 1 1</scale>
            </mesh>
          </geometry>
          <material>
            <script>
              <name>Gazebo/Gold</name>
              <uri>__default__</uri>
            </script>
            <specular>1 1 1 1</specular>
          </material>
        </visual>
        <self_collide>0</self_collide>
        <kinematic>0</kinematic>
        <gravity>1</gravity>
      </link>
      <joint name='joint_14' type='revolute'>
        <parent>module_14</parent>
        <child>module_15</child>
        <pose frame=''>0.035 0 0 1.5708 -0 0</pose>
        <axis>
          <xyz>0 0 1</xyz>
          <limit>
            <lower>-1.5708</lower>
            <upper>1.5708</upper>
            <effort>7</effort>
            <velocity>2.20893</velocity>
          </limit>
          <dynamics>
            <friction>0.2</friction>
            <spring_reference>0</spring_reference>
            <spring_stiffness>0</spring_stiffness>
          </dynamics>
          <use_parent_model_frame>0</use_parent_model_frame>
        </axis>
      </joint>
      <link name='module_15'>
        <pose frame=''>-0.896 0 0.03 0 -0 0</pose>
        <inertial>
          <pose frame=''>0 0 0 0 -0 0</pose>
          <mass>0.1</mass>
          <inertia>
            <ixx>3.38e-05</ixx>
            <ixy>0</ixy>
            <ixz>0</ixz>
            <iyy>4.69e-05</iyy>
            <iyz>0</iyz>
            <izz>4.69e-05</izz>
          </inertia>
        </inertial>
        <collision name='module_15_collision'>
          <pose frame=''>0 0 0 3.14159 -1.57079 3.14159</pose>
          <geometry>
            <cylinder>
              <radius>0.026</radius>
              <length>0.03</length>
            </cylinder>
          </geometry>
          <max_contacts>10</max_contacts>
          <surface>
            <contact>
              <ode/>
            </contact>
            <bounce/>
            <friction>
              <torsional>
                <ode/>
              </torsional>
              <ode/>
            </friction>
          </surface>
        </collision>
        <visual name='module_15_visual'>
          <pose frame=''>0 0 0 3.14159 -1.57079 3.14159</pose>
          <geometry>
            <cylinder>
              <radius>0.026</radius>
              <length>0.01</length>
            </cylinder>
          </geometry>
          <material>
            <script>
              <name>Gazebo/Red</name>
              <uri>__default__</uri>
            </script>
            <specular>1 1 1 1</specular>
          </material>
        </visual>
        <visual name='module_15_visual_mesh_i'>
          <pose frame=''>-0.03 0 0 0 -0 1.5708</pose>
          <geometry>
            <mesh>
              <uri>/home/li/Downloads/wheel_less_snake/src/wl_snake_description/meshes/rotary_input.dae</uri>
              <scale>1 1 1</scale>
            </mesh>
          </geometry>
          <material>
            <script>
              <name>Gazebo/Gold</name>
              <uri>__default__</uri>
            </script>
            <specular>1 1 1 1</specular>
          </material>
        </visual>
        <visual name='module_15_visual_mesh_o'>
          <pose frame=''>0.032 0 0 1.57079 1.57079 3.14159</pose>
          <geometry>
            <mesh>
              <uri>/home/li/Downloads/wheel_less_snake/src/wl_snake_description/meshes/rotary_output.dae</uri>
              <scale>1 1 1</scale>
            </mesh>
          </geometry>
          <material>
            <script>
              <name>Gazebo/Gold</name>
              <uri>__default__</uri>
            </script>
            <specular>1 1 1 1</specular>
          </material>
        </visual>
        <self_collide>0</self_collide>
        <kinematic>0</kinematic>
        <gravity>1</gravity>
      </link>
      <joint name='joint_15' type='revolute'>
        <parent>module_15</parent>
        <child>module_16</child>
        <pose frame=''>0.035 0 0 3.14159 -0 0</pose>
        <axis>
          <xyz>0 0 1</xyz>
          <limit>
            <lower>-1.5708</lower>
            <upper>1.5708</upper>
            <effort>7</effort>
            <velocity>2.20893</velocity>
          </limit>
          <dynamics>
            <friction>0.2</friction>
            <spring_reference>0</spring_reference>
            <spring_stiffness>0</spring_stiffness>
          </dynamics>
          <use_parent_model_frame>0</use_parent_model_frame>
        </axis>
      </joint>
      <link name='module_16'>
        <pose frame=''>-0.96 0 0.03 0 -0 0</pose>
        <inertial>
          <pose frame=''>0 0 0 0 -0 0</pose>
          <mass>0.1</mass>
          <inertia>
            <ixx>3.38e-05</ixx>
            <ixy>0</ixy>
            <ixz>0</ixz>
            <iyy>4.69e-05</iyy>
            <iyz>0</iyz>
            <izz>4.69e-05</izz>
          </inertia>
        </inertial>
        <collision name='module_16_collision'>
          <pose frame=''>0 0 0 3.14159 -1.57079 3.14159</pose>
          <geometry>
            <cylinder>
              <radius>0.026</radius>
              <length>0.03</length>
            </cylinder>
          </geometry>
          <max_contacts>10</max_contacts>
          <surface>
            <contact>
              <ode/>
            </contact>
            <bounce/>
            <friction>
              <torsional>
                <ode/>
              </torsional>
              <ode/>
            </friction>
          </surface>
        </collision>
        <visual name='module_16_visual'>
          <pose frame=''>0 0 0 3.14159 -1.57079 3.14159</pose>
          <geometry>
            <cylinder>
              <radius>0.026</radius>
              <length>0.01</length>
            </cylinder>
          </geometry>
          <material>
            <script>
              <name>Gazebo/Black</name>
              <uri>__default__</uri>
            </script>
            <specular>1 1 1 1</specular>
          </material>
        </visual>
        <visual name='module_16_visual_mesh_i'>
          <pose frame=''>-0.03 0 0 -1.57079 -1.57079 3.14159</pose>
          <geometry>
            <mesh>
              <uri>/home/li/Downloads/wheel_less_snake/src/wl_snake_description/meshes/rotary_input.dae</uri>
              <scale>1 1 1</scale>
            </mesh>
          </geometry>
          <material>
            <script>
              <name>Gazebo/Gold</name>
              <uri>__default__</uri>
            </script>
            <specular>1 1 1 1</specular>
          </material>
        </visual>
        <visual name='module_16_visual_mesh_o'>
          <pose frame=''>0.032 0 0 0 -0 1.5708</pose>
          <geometry>
            <mesh>
              <uri>/home/li/Downloads/wheel_less_snake/src/wl_snake_description/meshes/rotary_output.dae</uri>
              <scale>1 1 1</scale>
            </mesh>
          </geometry>
          <material>
            <script>
              <name>Gazebo/Gold</name>
              <uri>__default__</uri>
            </script>
            <specular>1 1 1 1</specular>
          </material>
        </visual>
        <self_collide>0</self_collide>
        <kinematic>0</kinematic>
        <gravity>1</gravity>
      </link>
      <joint name='joint_16' type='revolute'>
        <parent>module_16</parent>
        <child>module_17</child>
        <pose frame=''>0.035 0 0 -1.5708 -0 0</pose>
        <axis>
          <xyz>0 0 1</xyz>
          <limit>
            <lower>-1.5708</lower>
            <upper>1.5708</upper>
            <effort>7</effort>
            <velocity>2.20893</velocity>
          </limit>
          <dynamics>
            <friction>0.2</friction>
            <spring_reference>0</spring_reference>
            <spring_stiffness>0</spring_stiffness>
          </dynamics>
          <use_parent_model_frame>0</use_parent_model_frame>
        </axis>
      </joint>
      <link name='module_17'>
        <pose frame=''>-1.024 0 0.03 0 -0 0</pose>
        <inertial>
          <pose frame=''>0 0 0 0 -0 0</pose>
          <mass>0.1</mass>
          <inertia>
            <ixx>3.38e-05</ixx>
            <ixy>0</ixy>
            <ixz>0</ixz>
            <iyy>4.69e-05</iyy>
            <iyz>0</iyz>
            <izz>4.69e-05</izz>
          </inertia>
        </inertial>
        <collision name='module_17_collision'>
          <pose frame=''>0 0 0 3.14159 -1.57079 3.14159</pose>
          <geometry>
            <cylinder>
              <radius>0.026</radius>
              <length>0.03</length>
            </cylinder>
          </geometry>
          <max_contacts>10</max_contacts>
          <surface>
            <contact>
              <ode/>
            </contact>
            <bounce/>
            <friction>
              <torsional>
                <ode/>
              </torsional>
              <ode/>
            </friction>
          </surface>
        </collision>
        <visual name='module_17_visual'>
          <pose frame=''>0 0 0 3.14159 -1.57079 3.14159</pose>
          <geometry>
            <cylinder>
              <radius>0.026</radius>
              <length>0.01</length>
            </cylinder>
          </geometry>
          <material>
            <script>
              <name>Gazebo/Red</name>
              <uri>__default__</uri>
            </script>
            <specular>1 1 1 1</specular>
          </material>
        </visual>
        <visual name='module_17_visual_mesh_i'>
          <pose frame=''>-0.03 0 0 3.14159 -0 -1.5708</pose>
          <geometry>
            <mesh>
              <uri>/home/li/Downloads/wheel_less_snake/src/wl_snake_description/meshes/rotary_input.dae</uri>
              <scale>1 1 1</scale>
            </mesh>
          </geometry>
          <material>
            <script>
              <name>Gazebo/Gold</name>
              <uri>__default__</uri>
            </script>
            <specular>1 1 1 1</specular>
          </material>
        </visual>
        <visual name='module_17_visual_mesh_o'>
          <pose frame=''>0.032 0 0 -1.57079 -1.57079 3.14159</pose>
          <geometry>
            <mesh>
              <uri>/home/li/Downloads/wheel_less_snake/src/wl_snake_description/meshes/rotary_output.dae</uri>
              <scale>1 1 1</scale>
            </mesh>
          </geometry>
          <material>
            <script>
              <name>Gazebo/Gold</name>
              <uri>__default__</uri>
            </script>
            <specular>1 1 1 1</specular>
          </material>
        </visual>
        <self_collide>0</self_collide>
        <kinematic>0</kinematic>
        <gravity>1</gravity>
      </link>
      <plugin name='snake_control' filename='libgeneric_controller_plugin.so'>
        <controller joint_name='joint_1'>
          <pid>100.0 0.0 0.0</pid>
          <type>position</type>
        </controller>
        <controller joint_name='joint_2'>
          <pid>100.0 0.0 0.0</pid>
          <type>position</type>
        </controller>
        <controller joint_name='joint_3'>
          <pid>100.0 0.0 0.0</pid>
          <type>position</type>
        </controller>
        <controller joint_name='joint_4'>
          <pid>100.0 0.0 0.0</pid>
          <type>position</type>
        </controller>
        <controller joint_name='joint_5'>
          <pid>100.0 0.0 0.0</pid>
          <type>position</type>
        </controller>
        <controller joint_name='joint_6'>
          <pid>100.0 0.0 0.0</pid>
          <type>position</type>
        </controller>
        <controller joint_name='joint_7'>
          <pid>100.0 0.0 0.0</pid>
          <type>position</type>
        </controller>
        <controller joint_name='joint_8'>
          <pid>100.0 0.0 0.0</pid>
          <type>position</type>
        </controller>
        <controller joint_name='joint_9'>
          <pid>100.0 0.0 0.0</pid>
          <type>position</type>
        </controller>
        <controller joint_name='joint_10'>
          <pid>100.0 0.0 0.0</pid>
          <type>position</type>
        </controller>
        <controller joint_name='joint_11'>
          <pid>100.0 0.0 0.0</pid>
          <type>position</type>
        </controller>
        <controller joint_name='joint_12'>
          <pid>100.0 0.0 0.0</pid>
          <type>position</type>
        </controller>
        <controller joint_name='joint_13'>
          <pid>100.0 0.0 0.0</pid>
          <type>position</type>
        </controller>
        <controller joint_name='joint_14'>
          <pid>100.0 0.0 0.0</pid>
          <type>position</type>
        </controller>
        <controller joint_name='joint_15'>
          <pid>100.0 0.0 0.0</pid>
          <type>position</type>
        </controller>
        <controller joint_name='joint_16'>
          <pid>100.0 0.0 0.0</pid>
          <type>position</type>
        </controller>
        <robotNamespace>/</robotNamespace>
      </plugin>
      <pose frame=''>0 0 0 0 -0 0</pose>
    </model>
    <model name='stairs'>
      <pose frame=''>2.68348 0.008159 0 0 -0 0</pose>
      <link name='Stairs_1'>
        <visual name='Stairs_1_Visual_0'>
          <pose frame=''>-2.595 -1.14167 0.083333 0 -0 0</pose>
          <geometry>
            <box>
              <size>1 0.233333 0.166667</size>
            </box>
          </geometry>
          <material>
            <script>
              <uri>file://media/materials/scripts/gazebo.material</uri>
              <name>Gazebo/Grey</name>
            </script>
            <ambient>1 1 1 1</ambient>
          </material>
          <meta>
            <layer>0</layer>
          </meta>
        </visual>
        <collision name='Stairs_1_Collision_0'>
          <geometry>
            <box>
              <size>1 0.233333 0.166667</size>
            </box>
          </geometry>
          <pose frame=''>-2.595 -1.14167 0.083333 0 -0 0</pose>
          <max_contacts>10</max_contacts>
          <surface>
            <contact>
              <ode/>
            </contact>
            <bounce/>
            <friction>
              <torsional>
                <ode/>
              </torsional>
              <ode/>
            </friction>
          </surface>
        </collision>
        <visual name='Stairs_1_Visual_1'>
          <pose frame=''>-2.595 -1.375 0.25 0 -0 0</pose>
          <geometry>
            <box>
              <size>1 0.233333 0.166667</size>
            </box>
          </geometry>
          <material>
            <script>
              <uri>file://media/materials/scripts/gazebo.material</uri>
              <name>Gazebo/Grey</name>
            </script>
            <ambient>1 1 1 1</ambient>
          </material>
          <meta>
            <layer>0</layer>
          </meta>
        </visual>
        <collision name='Stairs_1_Collision_1'>
          <geometry>
            <box>
              <size>1 0.233333 0.166667</size>
            </box>
          </geometry>
          <pose frame=''>-2.595 -1.375 0.25 0 -0 0</pose>
          <max_contacts>10</max_contacts>
          <surface>
            <contact>
              <ode/>
            </contact>
            <bounce/>
            <friction>
              <torsional>
                <ode/>
              </torsional>
              <ode/>
            </friction>
          </surface>
        </collision>
        <visual name='Stairs_1_Visual_2'>
          <pose frame=''>-2.595 -1.60833 0.416667 0 -0 0</pose>
          <geometry>
            <box>
              <size>1 0.233333 0.166667</size>
            </box>
          </geometry>
          <material>
            <script>
              <uri>file://media/materials/scripts/gazebo.material</uri>
              <name>Gazebo/Grey</name>
            </script>
            <ambient>1 1 1 1</ambient>
          </material>
          <meta>
            <layer>0</layer>
          </meta>
        </visual>
        <collision name='Stairs_1_Collision_2'>
          <geometry>
            <box>
              <size>1 0.233333 0.166667</size>
            </box>
          </geometry>
          <pose frame=''>-2.595 -1.60833 0.416667 0 -0 0</pose>
          <max_contacts>10</max_contacts>
          <surface>
            <contact>
              <ode/>
            </contact>
            <bounce/>
            <friction>
              <torsional>
                <ode/>
              </torsional>
              <ode/>
            </friction>
          </surface>
        </collision>
        <visual name='Stairs_1_Visual_3'>
          <pose frame=''>-2.595 -1.84167 0.583333 0 -0 0</pose>
          <geometry>
            <box>
              <size>1 0.233333 0.166667</size>
            </box>
          </geometry>
          <material>
            <script>
              <uri>file://media/materials/scripts/gazebo.material</uri>
              <name>Gazebo/Grey</name>
            </script>
            <ambient>1 1 1 1</ambient>
          </material>
          <meta>
            <layer>0</layer>
          </meta>
        </visual>
        <collision name='Stairs_1_Collision_3'>
          <geometry>
            <box>
              <size>1 0.233333 0.166667</size>
            </box>
          </geometry>
          <pose frame=''>-2.595 -1.84167 0.583333 0 -0 0</pose>
          <max_contacts>10</max_contacts>
          <surface>
            <contact>
              <ode/>
            </contact>
            <bounce/>
            <friction>
              <torsional>
                <ode/>
              </torsional>
              <ode/>
            </friction>
          </surface>
        </collision>
        <visual name='Stairs_1_Visual_4'>
          <pose frame=''>-2.595 -2.075 0.75 0 -0 0</pose>
          <geometry>
            <box>
              <size>1 0.233333 0.166667</size>
            </box>
          </geometry>
          <material>
            <script>
              <uri>file://media/materials/scripts/gazebo.material</uri>
              <name>Gazebo/Grey</name>
            </script>
            <ambient>1 1 1 1</ambient>
          </material>
          <meta>
            <layer>0</layer>
          </meta>
        </visual>
        <collision name='Stairs_1_Collision_4'>
          <geometry>
            <box>
              <size>1 0.233333 0.166667</size>
            </box>
          </geometry>
          <pose frame=''>-2.595 -2.075 0.75 0 -0 0</pose>
          <max_contacts>10</max_contacts>
          <surface>
            <contact>
              <ode/>
            </contact>
            <bounce/>
            <friction>
              <torsional>
                <ode/>
              </torsional>
              <ode/>
            </friction>
          </surface>
        </collision>
        <visual name='Stairs_1_Visual_5'>
          <pose frame=''>-2.595 -2.30833 0.916667 0 -0 0</pose>
          <geometry>
            <box>
              <size>1 0.233333 0.166667</size>
            </box>
          </geometry>
          <material>
            <script>
              <uri>file://media/materials/scripts/gazebo.material</uri>
              <name>Gazebo/Grey</name>
            </script>
            <ambient>1 1 1 1</ambient>
          </material>
          <meta>
            <layer>0</layer>
          </meta>
        </visual>
        <collision name='Stairs_1_Collision_5'>
          <geometry>
            <box>
              <size>1 0.233333 0.166667</size>
            </box>
          </geometry>
          <pose frame=''>-2.595 -2.30833 0.916667 0 -0 0</pose>
          <max_contacts>10</max_contacts>
          <surface>
            <contact>
              <ode/>
            </contact>
            <bounce/>
            <friction>
              <torsional>
                <ode/>
              </torsional>
              <ode/>
            </friction>
          </surface>
        </collision>
        <visual name='Stairs_1_Visual_6'>
          <pose frame=''>-2.595 -2.54167 1.08333 0 -0 0</pose>
          <geometry>
            <box>
              <size>1 0.233333 0.166667</size>
            </box>
          </geometry>
          <material>
            <script>
              <uri>file://media/materials/scripts/gazebo.material</uri>
              <name>Gazebo/Grey</name>
            </script>
            <ambient>1 1 1 1</ambient>
          </material>
          <meta>
            <layer>0</layer>
          </meta>
        </visual>
        <collision name='Stairs_1_Collision_6'>
          <geometry>
            <box>
              <size>1 0.233333 0.166667</size>
            </box>
          </geometry>
          <pose frame=''>-2.595 -2.54167 1.08333 0 -0 0</pose>
          <max_contacts>10</max_contacts>
          <surface>
            <contact>
              <ode/>
            </contact>
            <bounce/>
            <friction>
              <torsional>
                <ode/>
              </torsional>
              <ode/>
            </friction>
          </surface>
        </collision>
        <visual name='Stairs_1_Visual_7'>
          <pose frame=''>-2.595 -2.775 1.25 0 -0 0</pose>
          <geometry>
            <box>
              <size>1 0.233333 0.166667</size>
            </box>
          </geometry>
          <material>
            <script>
              <uri>file://media/materials/scripts/gazebo.material</uri>
              <name>Gazebo/Grey</name>
            </script>
            <ambient>1 1 1 1</ambient>
          </material>
          <meta>
            <layer>0</layer>
          </meta>
        </visual>
        <collision name='Stairs_1_Collision_7'>
          <geometry>
            <box>
              <size>1 0.233333 0.166667</size>
            </box>
          </geometry>
          <pose frame=''>-2.595 -2.775 1.25 0 -0 0</pose>
          <max_contacts>10</max_contacts>
          <surface>
            <contact>
              <ode/>
            </contact>
            <bounce/>
            <friction>
              <torsional>
                <ode/>
              </torsional>
              <ode/>
            </friction>
          </surface>
        </collision>
        <visual name='Stairs_1_Visual_8'>
          <pose frame=''>-2.595 -3.00833 1.41667 0 -0 0</pose>
          <geometry>
            <box>
              <size>1 0.233333 0.166667</size>
            </box>
          </geometry>
          <material>
            <script>
              <uri>file://media/materials/scripts/gazebo.material</uri>
              <name>Gazebo/Grey</name>
            </script>
            <ambient>1 1 1 1</ambient>
          </material>
          <meta>
            <layer>0</layer>
          </meta>
        </visual>
        <collision name='Stairs_1_Collision_8'>
          <geometry>
            <box>
              <size>1 0.233333 0.166667</size>
            </box>
          </geometry>
          <pose frame=''>-2.595 -3.00833 1.41667 0 -0 0</pose>
          <max_contacts>10</max_contacts>
          <surface>
            <contact>
              <ode/>
            </contact>
            <bounce/>
            <friction>
              <torsional>
                <ode/>
              </torsional>
              <ode/>
            </friction>
          </surface>
        </collision>
        <visual name='Stairs_1_Visual_9'>
          <pose frame=''>-2.595 -3.24167 1.58333 0 -0 0</pose>
          <geometry>
            <box>
              <size>1 0.233333 0.166667</size>
            </box>
          </geometry>
          <material>
            <script>
              <uri>file://media/materials/scripts/gazebo.material</uri>
              <name>Gazebo/Grey</name>
            </script>
            <ambient>1 1 1 1</ambient>
          </material>
          <meta>
            <layer>0</layer>
          </meta>
        </visual>
        <collision name='Stairs_1_Collision_9'>
          <geometry>
            <box>
              <size>1 0.233333 0.166667</size>
            </box>
          </geometry>
          <pose frame=''>-2.595 -3.24167 1.58333 0 -0 0</pose>
          <max_contacts>10</max_contacts>
          <surface>
            <contact>
              <ode/>
            </contact>
            <bounce/>
            <friction>
              <torsional>
                <ode/>
              </torsional>
              <ode/>
            </friction>
          </surface>
        </collision>
        <visual name='Stairs_1_Visual_10'>
          <pose frame=''>-2.595 -3.475 1.75 0 -0 0</pose>
          <geometry>
            <box>
              <size>1 0.233333 0.166667</size>
            </box>
          </geometry>
          <material>
            <script>
              <uri>file://media/materials/scripts/gazebo.material</uri>
              <name>Gazebo/Grey</name>
            </script>
            <ambient>1 1 1 1</ambient>
          </material>
          <meta>
            <layer>0</layer>
          </meta>
        </visual>
        <collision name='Stairs_1_Collision_10'>
          <geometry>
            <box>
              <size>1 0.233333 0.166667</size>
            </box>
          </geometry>
          <pose frame=''>-2.595 -3.475 1.75 0 -0 0</pose>
          <max_contacts>10</max_contacts>
          <surface>
            <contact>
              <ode/>
            </contact>
            <bounce/>
            <friction>
              <torsional>
                <ode/>
              </torsional>
              <ode/>
            </friction>
          </surface>
        </collision>
        <visual name='Stairs_1_Visual_11'>
          <pose frame=''>-2.595 -3.70833 1.91667 0 -0 0</pose>
          <geometry>
            <box>
              <size>1 0.233333 0.166667</size>
            </box>
          </geometry>
          <material>
            <script>
              <uri>file://media/materials/scripts/gazebo.material</uri>
              <name>Gazebo/Grey</name>
            </script>
            <ambient>1 1 1 1</ambient>
          </material>
          <meta>
            <layer>0</layer>
          </meta>
        </visual>
        <collision name='Stairs_1_Collision_11'>
          <geometry>
            <box>
              <size>1 0.233333 0.166667</size>
            </box>
          </geometry>
          <pose frame=''>-2.595 -3.70833 1.91667 0 -0 0</pose>
          <max_contacts>10</max_contacts>
          <surface>
            <contact>
              <ode/>
            </contact>
            <bounce/>
            <friction>
              <torsional>
                <ode/>
              </torsional>
              <ode/>
            </friction>
          </surface>
        </collision>
        <visual name='Stairs_1_Visual_12'>
          <pose frame=''>-2.595 -3.94167 2.08333 0 -0 0</pose>
          <geometry>
            <box>
              <size>1 0.233333 0.166667</size>
            </box>
          </geometry>
          <material>
            <script>
              <uri>file://media/materials/scripts/gazebo.material</uri>
              <name>Gazebo/Grey</name>
            </script>
            <ambient>1 1 1 1</ambient>
          </material>
          <meta>
            <layer>0</layer>
          </meta>
        </visual>
        <collision name='Stairs_1_Collision_12'>
          <geometry>
            <box>
              <size>1 0.233333 0.166667</size>
            </box>
          </geometry>
          <pose frame=''>-2.595 -3.94167 2.08333 0 -0 0</pose>
          <max_contacts>10</max_contacts>
          <surface>
            <contact>
              <ode/>
            </contact>
            <bounce/>
            <friction>
              <torsional>
                <ode/>
              </torsional>
              <ode/>
            </friction>
          </surface>
        </collision>
        <visual name='Stairs_1_Visual_13'>
          <pose frame=''>-2.595 -4.175 2.25 0 -0 0</pose>
          <geometry>
            <box>
              <size>1 0.233333 0.166667</size>
            </box>
          </geometry>
          <material>
            <script>
              <uri>file://media/materials/scripts/gazebo.material</uri>
              <name>Gazebo/Grey</name>
            </script>
            <ambient>1 1 1 1</ambient>
          </material>
          <meta>
            <layer>0</layer>
          </meta>
        </visual>
        <collision name='Stairs_1_Collision_13'>
          <geometry>
            <box>
              <size>1 0.233333 0.166667</size>
            </box>
          </geometry>
          <pose frame=''>-2.595 -4.175 2.25 0 -0 0</pose>
          <max_contacts>10</max_contacts>
          <surface>
            <contact>
              <ode/>
            </contact>
            <bounce/>
            <friction>
              <torsional>
                <ode/>
              </torsional>
              <ode/>
            </friction>
          </surface>
        </collision>
        <visual name='Stairs_1_Visual_14'>
          <pose frame=''>-2.595 -4.40833 2.41667 0 -0 0</pose>
          <geometry>
            <box>
              <size>1 0.233333 0.166667</size>
            </box>
          </geometry>
          <material>
            <script>
              <uri>file://media/materials/scripts/gazebo.material</uri>
              <name>Gazebo/Grey</name>
            </script>
            <ambient>1 1 1 1</ambient>
          </material>
          <meta>
            <layer>0</layer>
          </meta>
        </visual>
        <collision name='Stairs_1_Collision_14'>
          <geometry>
            <box>
              <size>1 0.233333 0.166667</size>
            </box>
          </geometry>
          <pose frame=''>-2.595 -4.40833 2.41667 0 -0 0</pose>
          <max_contacts>10</max_contacts>
          <surface>
            <contact>
              <ode/>
            </contact>
            <bounce/>
            <friction>
              <torsional>
                <ode/>
              </torsional>
              <ode/>
            </friction>
          </surface>
        </collision>
        <self_collide>0</self_collide>
        <kinematic>0</kinematic>
        <gravity>1</gravity>
      </link>
      <static>1</static>
    </model>
    <state world_name='default'>
      <sim_time>0 0</sim_time>
      <real_time>0 0</real_time>
      <wall_time>1542372209 407125440</wall_time>
      <iterations>0</iterations>
      <model name='pipe'>
        <pose frame=''>0 0 0 0 -0 0</pose>
        <scale>1 1 1</scale>
        <link name='link_pipe'>
          <pose frame=''>0 0 0 0 -0 0</pose>
          <velocity>0 0 0 0 -0 0</velocity>
          <acceleration>0 0 0 0 -0 0</acceleration>
          <wrench>0 0 0 0 -0 0</wrench>
        </link>
      </model>
      <model name='plane'>
        <pose frame=''>0 0 0 0 -0 0</pose>
        <scale>1 1 1</scale>
        <link name='link'>
          <pose frame=''>0 0 0 0 -0 0</pose>
          <velocity>0 0 0 0 -0 0</velocity>
          <acceleration>0 0 0 0 -0 0</acceleration>
          <wrench>0 0 0 0 -0 0</wrench>
        </link>
      </model>
      <model name='stairs'>
        <pose frame=''>2.68348 0.008159 0 0 -0 0</pose>
        <scale>1 1 1</scale>
        <link name='Stairs_1'>
          <pose frame=''>2.68348 0.008159 0 0 -0 0</pose>
          <velocity>0 0 0 0 -0 0</velocity>
          <acceleration>0 0 0 0 -0 0</acceleration>
          <wrench>0 0 0 0 -0 0</wrench>
        </link>
      </model>
      <model name='wl_snake'>
        <pose frame=''>0 0 0 0 -0 0</pose>
        <scale>1 1 1</scale>
        <link name='module_1'>
          <pose frame=''>0 0 0.03 0 -0 0</pose>
          <velocity>0 0 0 0 -0 0</velocity>
          <acceleration>0 0 0 0 -0 0</acceleration>
          <wrench>0 0 0 0 -0 0</wrench>
        </link>
        <link name='module_10'>
          <pose frame=''>-0.576 0 0.03 0 -0 0</pose>
          <velocity>0 0 0 0 -0 0</velocity>
          <acceleration>0 0 0 0 -0 0</acceleration>
          <wrench>0 0 0 0 -0 0</wrench>
        </link>
        <link name='module_11'>
          <pose frame=''>-0.64 0 0.03 0 -0 0</pose>
          <velocity>0 0 0 0 -0 0</velocity>
          <acceleration>0 0 0 0 -0 0</acceleration>
          <wrench>0 0 0 0 -0 0</wrench>
        </link>
        <link name='module_12'>
          <pose frame=''>-0.704 0 0.03 0 -0 0</pose>
          <velocity>0 0 0 0 -0 0</velocity>
          <acceleration>0 0 0 0 -0 0</acceleration>
          <wrench>0 0 0 0 -0 0</wrench>
        </link>
        <link name='module_13'>
          <pose frame=''>-0.768 0 0.03 0 -0 0</pose>
          <velocity>0 0 0 0 -0 0</velocity>
          <acceleration>0 0 0 0 -0 0</acceleration>
          <wrench>0 0 0 0 -0 0</wrench>
        </link>
        <link name='module_14'>
          <pose frame=''>-0.832 0 0.03 0 -0 0</pose>
          <velocity>0 0 0 0 -0 0</velocity>
          <acceleration>0 0 0 0 -0 0</acceleration>
          <wrench>0 0 0 0 -0 0</wrench>
        </link>
        <link name='module_15'>
          <pose frame=''>-0.896 0 0.03 0 -0 0</pose>
          <velocity>0 0 0 0 -0 0</velocity>
          <acceleration>0 0 0 0 -0 0</acceleration>
          <wrench>0 0 0 0 -0 0</wrench>
        </link>
        <link name='module_16'>
          <pose frame=''>-0.96 0 0.03 0 -0 0</pose>
          <velocity>0 0 0 0 -0 0</velocity>
          <acceleration>0 0 0 0 -0 0</acceleration>
          <wrench>0 0 0 0 -0 0</wrench>
        </link>
        <link name='module_17'>
          <pose frame=''>-1.024 0 0.03 0 -0 0</pose>
          <velocity>0 0 0 0 -0 0</velocity>
          <acceleration>0 0 0 0 -0 0</acceleration>
          <wrench>0 0 0 0 -0 0</wrench>
        </link>
        <link name='module_2'>
          <pose frame=''>-0.064 0 0.03 0 -0 0</pose>
          <velocity>0 0 0 0 -0 0</velocity>
          <acceleration>0 0 0 0 -0 0</acceleration>
          <wrench>0 0 0 0 -0 0</wrench>
        </link>
        <link name='module_3'>
          <pose frame=''>-0.128 0 0.03 0 -0 0</pose>
          <velocity>0 0 0 0 -0 0</velocity>
          <acceleration>0 0 0 0 -0 0</acceleration>
          <wrench>0 0 0 0 -0 0</wrench>
        </link>
        <link name='module_4'>
          <pose frame=''>-0.192 0 0.03 0 -0 0</pose>
          <velocity>0 0 0 0 -0 0</velocity>
          <acceleration>0 0 0 0 -0 0</acceleration>
          <wrench>0 0 0 0 -0 0</wrench>
        </link>
        <link name='module_5'>
          <pose frame=''>-0.256 0 0.03 0 -0 0</pose>
          <velocity>0 0 0 0 -0 0</velocity>
          <acceleration>0 0 0 0 -0 0</acceleration>
          <wrench>0 0 0 0 -0 0</wrench>
        </link>
        <link name='module_6'>
          <pose frame=''>-0.32 0 0.03 0 -0 0</pose>
          <velocity>0 0 0 0 -0 0</velocity>
          <acceleration>0 0 0 0 -0 0</acceleration>
          <wrench>0 0 0 0 -0 0</wrench>
        </link>
        <link name='module_7'>
          <pose frame=''>-0.384 0 0.03 0 -0 0</pose>
          <velocity>0 0 0 0 -0 0</velocity>
          <acceleration>0 0 0 0 -0 0</acceleration>
          <wrench>0 0 0 0 -0 0</wrench>
        </link>
        <link name='module_8'>
          <pose frame=''>-0.448 0 0.03 0 -0 0</pose>
          <velocity>0 0 0 0 -0 0</velocity>
          <acceleration>0 0 0 0 -0 0</acceleration>
          <wrench>0 0 0 0 -0 0</wrench>
        </link>
        <link name='module_9'>
          <pose frame=''>-0.512 0 0.03 0 -0 0</pose>
          <velocity>0 0 0 0 -0 0</velocity>
          <acceleration>0 0 0 0 -0 0</acceleration>
          <wrench>0 0 0 0 -0 0</wrench>
        </link>
      </model>
      <light name='sun'>
        <pose frame=''>-11.8208 -19.3843 17.2198 0 -0 0</pose>
      </light>
    </state>
    <gui fullscreen='0'>
      <camera name='user_camera'>
        <pose frame=''>5 -5 2 0 0.275643 2.35619</pose>
        <view_controller>orbit</view_controller>
        <projection_type>perspective</projection_type>
      </camera>
    </gui>
  </world>
</sdf>
